Workbook
Name requiredAttributePTDMap: [1]AttributePTDMAP!$A$1:$BT$59
Name optionalAttributePTDMap: [1]AttributePTDMAP!$A$60:$BT$506
Name preferredAttributePTDMap: [1]AttributePTDMAP!$A$507:$BT$537
Name attributeMapFeedProductType: [1]AttributePTDMAP!$B$1:$BT$1
Name CONDITION_LIST_0: '[1]Conditions List'!$A$2
Name CONDITION_LIST_1: '[1]Conditions List'!$B$2:$B$13
Name CONDITION_LIST_2: '[1]Conditions List'!$C$2
Name CONDITION_LIST_3: '[1]Conditions List'!$D$2
Name feed_product_type: '[1]Dropdown Lists'!$A$4:$A$74
Name AttributePTDMAP: [2]attributePTDMap!$A$1:$L135
Name dropdown_list_feed_product_type_: '[2]Dropdown Lists'!$C$4:$C$6
Name shirtrelationship_type: '[5]Dropdown Lists'!$B$4:$B$7
Name shirtage_range_description: '[5]Dropdown Lists'!$C$4:$C$8
Name shirtis_autographed: '[5]Dropdown Lists'!$D$4:$D$5
Name shirtitem_width_unit_of_measure: '[5]Dropdown Lists'!$E$4:$E$9
Name shirtshirt_size_system: '[5]Dropdown Lists'!$F$4
Name shirtcalifornia_proposition__chemical_names: '[5]Dropdown Lists'!$G$4:$G$869
Name shirtcountry_of_origin: '[5]Dropdown Lists'!$H$4:$H$271
Name shirtlithium_battery_packaging: '[5]Dropdown Lists'!$I$4:$I$6
Name shirtexternal_product_id_type: '[5]Dropdown Lists'!$J$4:$J$8
Name shirtvariation_theme: '[5]Dropdown Lists'!$K$4:$K$22
Name shirttarget_gender: '[5]Dropdown Lists'!$L$4:$L$6
Name shirtspecial_features: '[5]Dropdown Lists'!$M$4:$M$14
Name shirtclosure_type: '[5]Dropdown Lists'!$N$4:$N$26
Name shirtitem_type_name: '[5]Dropdown Lists'!$O$4:$O$32
Name shirtduration_unit_of_measure: '[5]Dropdown Lists'!$P$4
Name shirtneck_style: '[5]Dropdown Lists'!$Q$4:$Q$18
Name shirtcurrency: '[5]Dropdown Lists'!$R$4:$R$11
Name shirtsupplier_declared_dg_hz_regulation: '[5]Dropdown Lists'!$S$4:$S$10
Name shirtpesticide_marking_registration_status: '[5]Dropdown Lists'!$T$4:$T$6
Name shirtsport_type: '[5]Dropdown Lists'!$U$4:$U$84
Name shirtpesticide_marking_type: '[5]Dropdown Lists'!$V$4:$V$5
Name shirtregulation_type: '[5]Dropdown Lists'!$W$4:$W$10
Name shirtbelt_style: '[5]Dropdown Lists'!$X$4:$X$8
Name shirtbatteries_required: '[5]Dropdown Lists'!$Y$4:$Y$5
Name shirtshirt_sleeve_length_to: '[5]Dropdown Lists'!$Z$4:$Z$19
Name shirtbattery_cell_composition: '[5]Dropdown Lists'!$AA$4:$AA$36
Name shirtneck_size_unit_of_measure: '[5]Dropdown Lists'!$AB$4:$AB$8
Name shirtpackage_weight_unit_of_measure: '[5]Dropdown Lists'!$AC$4:$AC$8
Name shirtshirt_neck_size_to: '[5]Dropdown Lists'!$AD$4:$AD$15
Name shirtupdate_delete: '[5]Dropdown Lists'!$AE$4:$AE$6
Name shirtcolor_map: '[5]Dropdown Lists'!$AF$4:$AF$27
Name shirtare_batteries_included: '[5]Dropdown Lists'!$AG$4:$AG$5
Name shirtlegal_compliance_certification_status: '[5]Dropdown Lists'!$AH$4:$AH$6
Name shirtsubject_character: '[5]Dropdown Lists'!$AI$4:$AI$465
Name shirtsize_map: '[5]Dropdown Lists'!$AJ$4:$AJ$16
Name shirtshirt_height_type: '[5]Dropdown Lists'!$AK$4:$AK$8
Name shirtchest_size_unit_of_measure: '[5]Dropdown Lists'!$AL$4:$AL$8
Name shirtpattern_type: '[5]Dropdown Lists'!$AM$4:$AM$11
Name shirtunderwire_type: '[5]Dropdown Lists'!$AN$4:$AN$5
Name shirtshirt_size: '[5]Dropdown Lists'!$AO$4:$AO$129
Name shirtcpsia_cautionary_statement: '[5]Dropdown Lists'!$AP$4:$AP$11
Name shirtshirt_size_to: '[5]Dropdown Lists'!$AQ$4:$AQ$129
Name shirtteam_name: '[5]Dropdown Lists'!$AR$4
Name shirtshirt_body_type: '[5]Dropdown Lists'!$AS$4:$AS$7
Name shirtwebsite_shipping_weight_unit_of_measure: '[5]Dropdown Lists'!$AT$4:$AT$8
Name shirtcup_size: '[5]Dropdown Lists'!$AU$4:$AU$18
Name shirtprogressive_discount_type: '[5]Dropdown Lists'!$AV$4:$AV$5
Name shirtmaterial_type: '[5]Dropdown Lists'!$AW$4:$AW$21
Name shirtlithium_battery_weight_unit_of_measure: '[5]Dropdown Lists'!$AX$4:$AX$8

Sheet step02图片链接
A2: Size | B2: Color | C2: 項目③ | D2: 总数 | E2: メイン | F2: カラー | G2: Url1 | H2: Url2 | I2: Url3 | J2: Url4 | K2: Url5 | L2: Url6 | M2: Url7 | N2: Url8 | P2: 商品图片* | Q2: http://m.qpic.cn/psc?/V51r8tMy2oY6rP1cY0U82vBxqf0QfuKH/bqQfVz5yrrGYSXMvKr.cqeNiqyBUA20Xdqgq*JhR8t.w3IYn6tQIoc0H*.PP1ttTTaeN9xjEdQldNLlulT8RGqhmloAUM9aiU*mYyChSGaw!/b&bo=QAZABkAGQAYBFzA!&rf=viewer_4
A3: =[3]step01標題編集!A6 -> #REF! | B3: =[3]step01標題編集!B6 -> #REF! | C3: ='[4]step01 標題編集'!D6 -> 0 | D3: =IF(OR($A$3+$B$3+$C$3=0,$A$3*$B$3*$C$3=1),0,IF($A$3=0,1,$A$3)*IF($B$3=0,1,$B$3)*IF($C$3=0,1,$C$3)) -> #REF!
E4: _0 | G4: _1 | H4: _2 | I4: _3 | J4: _4 | K4: _5 | L4: _6 | M4: _7 | N4: _8
B5: =IF(step01标题尺码信息!B7="","",step01标题尺码信息!B7) | E5: http://m.qpic.cn/psc?/V50EJGsl1uIkSE1hk7qh4B5hbw1pcDzP/TmEUgtj9EK6.7V8ajmQrEOovUy7Nklm4ADJ*1A6bXM9Ps8GGT93nj.l8Bz.HoXAN91KxV2yr4x6AQJdHOquLm1yX2NhZZPYJFfthQn.qjT8!/b&bo=QAZABkAGQAYBJwA!&rf=viewer_4 | F5: http://m.qpic.cn/psc?/V50EJGsl1uIkSE1hk7qh4B5hbw1pcDzP/TmEUgtj9EK6.7V8ajmQrEOovUy7Nklm4ADJ*1A6bXM9vAQlkJZt3KbnEAMuAVGRXbuhYHSfZoPQ1L*9SPpVG3WaN5WOp260e20z*lHFx7D8!/b&bo=QAZABkAGQAYBFzA!&rf=viewer_4 | G5: http://m.qpic.cn/psc?/V50EJGsl1uIkSE1hk7qh4B5hbw1pcDzP/TmEUgtj9EK6.7V8ajmQrEDKikFbkkozfjrtZiFA2H09fGPTLFaFRjqsirDSUn7gRUa0JZySO9V04bH3mXqhlF7X5g1HKYLZ9SiPV2JmN*To!/b&bo=QAZABkAGQAYBByA!&rf=viewer_4 | H5: http://m.qpic.cn/psc?/V50EJGsl1uIkSE1hk7qh4B5hbw1pcDzP/TmEUgtj9EK6.7V8ajmQrEDKikFbkkozfjrtZiFA2H0.6Uhp1CJgEud4M19wB9UTXFPC8SWx.87IazvjUPKpHS8uhVMQz8WH1bXXkOQ9ellk!/b&bo=QAZABkAGQAYBFzA!&rf=viewer_4 | I5: http://m.qpic.cn/psc?/V50EJGsl1uIkSE1hk7qh4B5hbw1pcDzP/TmEUgtj9EK6.7V8ajmQrEDKikFbkkozfjrtZiFA2H0*nCVP.TqLwdsolddhbyUkF0PhqJ*XYfBrbHwgVOblC3XPOOUsyaBEdVBfOMNpx2DI!/b&bo=QAZABkAGQAYBJwA!&rf=viewer_4 | J5: http://m.qpic.cn/psc?/V50EJGsl1uIkSE1hk7qh4B5hbw1pcDzP/TmEUgtj9EK6.7V8ajmQrEDKikFbkkozfjrtZiFA2H080WOSvAxj2ht5WpVN4Fie67uUI8PWfZu9MX2ii1QGrwZokXjQG6CaGQCyaNUf*GoE!/b&bo=QAZABkAGQAYBFzA!&rf=viewer_4 | K5: http://m.qpic.cn/psc?/V50EJGsl1uIkSE1hk7qh4B5hbw1pcDzP/TmEUgtj9EK6.7V8ajmQrEBRAZRvjMGWHygmV.vC4tNTqrFH5VKNWbq0r205ZiWe6iZ7jdzY.REzlPyxF.Pt2YhUROcrqlwTfLWqkacDVUgE!/b&bo=QAZABkAGQAYBFzA!&rf=viewer_4
B6: =IF(step01标题尺码信息!B8="","",step01标题尺码信息!B8) | E6: http://m.qpic.cn/psc?/V50EJGsl1uIkSE1hk7qh4B5hbw1pcDzP/TmEUgtj9EK6.7V8ajmQrEBRAZRvjMGWHygmV.vC4tNRtPByXsSHURA623Z0zZyhPe4CcUcyErkYCvWQrsNaB.FSfcfxh889QcaY8*9PDk7c!/b&bo=QAZABkAGQAYBByA!&rf=viewer_4 | F6: http://m.qpic.cn/psc?/V50EJGsl1uIkSE1hk7qh4B5hbw1pcDzP/TmEUgtj9EK6.7V8ajmQrEBRAZRvjMGWHygmV.vC4tNRRYDddFb2*yOc7soIZDw9uGBb*gP6Um*5ghTkHnuYuj5*b7C*nGdoQuMFGq8.3I2E!/b&bo=QAZABkAGQAYBFzA!&rf=viewer_4 | G6: http://m.qpic.cn/psc?/V50EJGsl1uIkSE1hk7qh4B5hbw1pcDzP/TmEUgtj9EK6.7V8ajmQrEDKikFbkkozfjrtZiFA2H09fGPTLFaFRjqsirDSUn7gRUa0JZySO9V04bH3mXqhlF7X5g1HKYLZ9SiPV2JmN*To!/b&bo=QAZABkAGQAYBByA!&rf=viewer_4 | H6: http://m.qpic.cn/psc?/V50EJGsl1uIkSE1hk7qh4B5hbw1pcDzP/TmEUgtj9EK6.7V8ajmQrEDKikFbkkozfjrtZiFA2H0.6Uhp1CJgEud4M19wB9UTXFPC8SWx.87IazvjUPKpHS8uhVMQz8WH1bXXkOQ9ellk!/b&bo=QAZABkAGQAYBFzA!&rf=viewer_4 | I6: http://m.qpic.cn/psc?/V50EJGsl1uIkSE1hk7qh4B5hbw1pcDzP/TmEUgtj9EK6.7V8ajmQrEDKikFbkkozfjrtZiFA2H0*nCVP.TqLwdsolddhbyUkF0PhqJ*XYfBrbHwgVOblC3XPOOUsyaBEdVBfOMNpx2DI!/b&bo=QAZABkAGQAYBJwA!&rf=viewer_4 | J6: http://m.qpic.cn/psc?/V50EJGsl1uIkSE1hk7qh4B5hbw1pcDzP/TmEUgtj9EK6.7V8ajmQrEDKikFbkkozfjrtZiFA2H080WOSvAxj2ht5WpVN4Fie67uUI8PWfZu9MX2ii1QGrwZokXjQG6CaGQCyaNUf*GoE!/b&bo=QAZABkAGQAYBFzA!&rf=viewer_4 | K6: http://m.qpic.cn/psc?/V50EJGsl1uIkSE1hk7qh4B5hbw1pcDzP/TmEUgtj9EK6.7V8ajmQrEBRAZRvjMGWHygmV.vC4tNTqrFH5VKNWbq0r205ZiWe6iZ7jdzY.REzlPyxF.Pt2YhUROcrqlwTfLWqkacDVUgE!/b&bo=QAZABkAGQAYBFzA!&rf=viewer_4
B7: =IF(step01标题尺码信息!B9="","",step01标题尺码信息!B9) | E7: http://m.qpic.cn/psc?/V50EJGsl1uIkSE1hk7qh4B5hbw1pcDzP/TmEUgtj9EK6.7V8ajmQrEOovUy7Nklm4ADJ*1A6bXM.stRtTahTImQKeeeBSYyPL1tht9tnGJ2eRnuMftt.mQk1JwEln.vamrj.wTVrMN7Y!/b&bo=QAZABkAGQAYBByA!&rf=viewer_4 | F7: http://m.qpic.cn/psc?/V50EJGsl1uIkSE1hk7qh4B5hbw1pcDzP/TmEUgtj9EK6.7V8ajmQrEOovUy7Nklm4ADJ*1A6bXM8jwx8PaxLnMB*0DAew96F69M7UQHHLmJX5lvseRyC23qG16.8iBLPcFj3QwETfiuw!/b&bo=QAZABkAGQAYBFzA!&rf=viewer_4 | G7: http://m.qpic.cn/psc?/V50EJGsl1uIkSE1hk7qh4B5hbw1pcDzP/TmEUgtj9EK6.7V8ajmQrEDKikFbkkozfjrtZiFA2H09fGPTLFaFRjqsirDSUn7gRUa0JZySO9V04bH3mXqhlF7X5g1HKYLZ9SiPV2JmN*To!/b&bo=QAZABkAGQAYBByA!&rf=viewer_4 | H7: http://m.qpic.cn/psc?/V50EJGsl1uIkSE1hk7qh4B5hbw1pcDzP/TmEUgtj9EK6.7V8ajmQrEDKikFbkkozfjrtZiFA2H0.6Uhp1CJgEud4M19wB9UTXFPC8SWx.87IazvjUPKpHS8uhVMQz8WH1bXXkOQ9ellk!/b&bo=QAZABkAGQAYBFzA!&rf=viewer_4 | I7: http://m.qpic.cn/psc?/V50EJGsl1uIkSE1hk7qh4B5hbw1pcDzP/TmEUgtj9EK6.7V8ajmQrEDKikFbkkozfjrtZiFA2H0*nCVP.TqLwdsolddhbyUkF0PhqJ*XYfBrbHwgVOblC3XPOOUsyaBEdVBfOMNpx2DI!/b&bo=QAZABkAGQAYBJwA!&rf=viewer_4 | J7: http://m.qpic.cn/psc?/V50EJGsl1uIkSE1hk7qh4B5hbw1pcDzP/TmEUgtj9EK6.7V8ajmQrEDKikFbkkozfjrtZiFA2H080WOSvAxj2ht5WpVN4Fie67uUI8PWfZu9MX2ii1QGrwZokXjQG6CaGQCyaNUf*GoE!/b&bo=QAZABkAGQAYBFzA!&rf=viewer_4 | K7: http://m.qpic.cn/psc?/V50EJGsl1uIkSE1hk7qh4B5hbw1pcDzP/TmEUgtj9EK6.7V8ajmQrEBRAZRvjMGWHygmV.vC4tNTqrFH5VKNWbq0r205ZiWe6iZ7jdzY.REzlPyxF.Pt2YhUROcrqlwTfLWqkacDVUgE!/b&bo=QAZABkAGQAYBFzA!&rf=viewer_4
B8: =IF(step01标题尺码信息!B11="","",step01标题尺码信息!B11)
A9: =IF('[4]step01 標題編集'!A11="","",'[4]step01 標題編集'!A11) | B9: =IF(step01标题尺码信息!B12="","",step01标题尺码信息!B12)
A10: =IF('[4]step01 標題編集'!A12="","",'[4]step01 標題編集'!A12) | B10: =IF(step01标题尺码信息!B13="","",step01标题尺码信息!B13)
A11: =IF('[4]step01 標題編集'!A13="","",'[4]step01 標題編集'!A13) | B11: =IF(step01标题尺码信息!B14="","",step01标题尺码信息!B14)
A12: =IF('[4]step01 標題編集'!A14="","",'[4]step01 標題編集'!A14) | B12: =IF(step01标题尺码信息!#REF!="","",step01标题尺码信息!#REF!) -> #REF!
A13: =IF('[4]step01 標題編集'!A15="","",'[4]step01 標題編集'!A15) | B13: =IF(step01标题尺码信息!B15="","",step01标题尺码信息!B15)
A14: =IF('[4]step01 標題編集'!A16="","",'[4]step01 標題編集'!A16) | B14: =IF(step01标题尺码信息!B16="","",step01标题尺码信息!B16)
A15: =IF('[4]step01 標題編集'!A17="","",'[4]step01 標題編集'!A17) | B15: =IF(step01标题尺码信息!B17="","",step01标题尺码信息!B17)
A16: =IF('[4]step01 標題編集'!A18="","",'[4]step01 標題編集'!A18) | B16: =IF(step01标题尺码信息!B18="","",step01标题尺码信息!B18) | E16: =IF(""=IFERROR(VLOOKUP([4]temp!$A$1&"_"&$B16,#REF!,2,FALSE),""),"",IFERROR(VLOOKUP([4]temp!$A$1&"_"&$B16,#REF!,2,FALSE),""))
A17: =IF('[4]step01 標題編集'!A19="","",'[4]step01 標題編集'!A19) | B17: =IF(step01标题尺码信息!B19="","",step01标题尺码信息!B19) | E17: =IF(""=IFERROR(VLOOKUP([4]temp!$A$1&"_"&$B17,#REF!,2,FALSE),""),"",IFERROR(VLOOKUP([4]temp!$A$1&"_"&$B17,#REF!,2,FALSE),""))
A18: =IF('[4]step01 標題編集'!A20="","",'[4]step01 標題編集'!A20) | B18: =IF(step01标题尺码信息!B20="","",step01标题尺码信息!B20) | E18: =IF(""=IFERROR(VLOOKUP([4]temp!$A$1&"_"&$B18,#REF!,2,FALSE),""),"",IFERROR(VLOOKUP([4]temp!$A$1&"_"&$B18,#REF!,2,FALSE),""))
A19: =IF('[4]step01 標題編集'!A21="","",'[4]step01 標題編集'!A21) | B19: =IF(step01标题尺码信息!B21="","",step01标题尺码信息!B21) | E19: =IF(""=IFERROR(VLOOKUP([4]temp!$A$1&"_"&$B19,#REF!,2,FALSE),""),"",IFERROR(VLOOKUP([4]temp!$A$1&"_"&$B19,#REF!,2,FALSE),""))
A20: =IF('[4]step01 標題編集'!A22="","",'[4]step01 標題編集'!A22) | B20: =IF(step01标题尺码信息!B22="","",step01标题尺码信息!B22) | E20: =IF(""=IFERROR(VLOOKUP([4]temp!$A$1&"_"&$B20,#REF!,2,FALSE),""),"",IFERROR(VLOOKUP([4]temp!$A$1&"_"&$B20,#REF!,2,FALSE),""))
A21: =IF('[4]step01 標題編集'!A23="","",'[4]step01 標題編集'!A23) | B21: =IF(step01标题尺码信息!B23="","",step01标题尺码信息!B23) | E21: =IF(""=IFERROR(VLOOKUP([4]temp!$A$1&"_"&$B21,#REF!,2,FALSE),""),"",IFERROR(VLOOKUP([4]temp!$A$1&"_"&$B21,#REF!,2,FALSE),""))
A22: =IF('[4]step01 標題編集'!A24="","",'[4]step01 標題編集'!A24) | B22: =IF(step01标题尺码信息!B24="","",step01标题尺码信息!B24) | E22: =IF(""=IFERROR(VLOOKUP([4]temp!$A$1&"_"&$B22,#REF!,2,FALSE),""),"",IFERROR(VLOOKUP([4]temp!$A$1&"_"&$B22,#REF!,2,FALSE),""))
A23: =IF('[4]step01 標題編集'!A25="","",'[4]step01 標題編集'!A25) | B23: =IF(step01标题尺码信息!B25="","",step01标题尺码信息!B25) | E23: =IF(""=IFERROR(VLOOKUP([4]temp!$A$1&"_"&$B23,#REF!,2,FALSE),""),"",IFERROR(VLOOKUP([4]temp!$A$1&"_"&$B23,#REF!,2,FALSE),""))
A24: =IF('[4]step01 標題編集'!A26="","",'[4]step01 標題編集'!A26) | B24: =IF(step01标题尺码信息!B26="","",step01标题尺码信息!B26) | E24: =IF(""=IFERROR(VLOOKUP([4]temp!$A$1&"_"&$B24,#REF!,2,FALSE),""),"",IFERROR(VLOOKUP([4]temp!$A$1&"_"&$B24,#REF!,2,FALSE),""))
A25: =IF('[4]step01 標題編集'!A27="","",'[4]step01 標題編集'!A27) | B25: =IF(step01标题尺码信息!B27="","",step01标题尺码信息!B27) | E25: =IF(""=IFERROR(VLOOKUP([4]temp!$A$1&"_"&$B25,#REF!,2,FALSE),""),"",IFERROR(VLOOKUP([4]temp!$A$1&"_"&$B25,#REF!,2,FALSE),""))
A26: =IF('[4]step01 標題編集'!A28="","",'[4]step01 標題編集'!A28) | B26: =IF(step01标题尺码信息!B28="","",step01标题尺码信息!B28) | E26: =IF(""=IFERROR(VLOOKUP([4]temp!$A$1&"_"&$B26,#REF!,2,FALSE),""),"",IFERROR(VLOOKUP([4]temp!$A$1&"_"&$B26,#REF!,2,FALSE),""))
A27: =IF('[4]step01 標題編集'!A29="","",'[4]step01 標題編集'!A29) | B27: =IF(step01标题尺码信息!B29="","",step01标题尺码信息!B29) | E27: =IF(""=IFERROR(VLOOKUP([4]temp!$A$1&"_"&$B27,#REF!,2,FALSE),""),"",IFERROR(VLOOKUP([4]temp!$A$1&"_"&$B27,#REF!,2,FALSE),""))
... A115: =IF('[4]step01 標題編集'!A117="","",'[4]step01 標題編集'!A117) | B115: =IF(step01标题尺码信息!B117="","",step01标题尺码信息!B117) | E115: =IF(""=IFERROR(VLOOKUP([4]temp!$A$1&"_"&$B115,#REF!,2,FALSE),""),"",IFERROR(VLOOKUP([4]temp!$A$1&"_"&$B115,#REF!,2,FALSE),""))

Sheet step01标题尺码信息
A1: 店铺名称 | B1: VH051- | D1: SKU | F1: 商品标题 | Q1: =LENB(G1)+LENB(B3)+MAX(F7:F300) -> 0 | R1: 商品售价（美元） | S1: 45 | U1: 适用性别 | V1: Unisex
A2: 员工号 | F2: 商品副标题 | G2: ikTok changed my life for the better tshirt | Q2: =LENB(B2) -> 0 | R2: 商品原价（美元） | S2: 58 | U2: 年龄范围 | V2: Adult
A3: 类目 | D3: 品牌 | E3: Vasarhely | F3: =IF(ISERROR(FIND(E3,B3)),"警告：请保持商品標識与ブランド保持一致","") -> 警告：请保持商品標識与ブランド保持一致 | G3: 类目 | H3: Ski | O3: 是否鞋类 | P3: 否 | R3: 成本价（美元） | S3: 20
G4: 商品SKU | H4: 項目分類 | J4: 商品名複製用 | M4: Color | N4: 颜色 | O4: Size | P4: 尺码 | R4: SEO
A5: 尺码 | B5: 颜色 | C5: Color | D5: 項目③ | E5: 総数 | J5: ="判定："&COUNTIF($I$7:$I$105,1)&"/"&$E$6 -> 判定：0/0
A6: =IF(COUNTA(A$7:A$35)=0,0,COUNTA(A$7:A$35)) -> 0 | B6: =IF(COUNTA(B$7:B$35)=0,0,COUNTA(B$7:B$35)) -> 0 | C6: 6 | D6: =IF(COUNTA(D$7:D$35)=0,0,COUNTA(D$7:D$35)) -> 0 | E6: =IF(OR($A$6+$B$6+$D$6=0,$A$6*$B$6*$D$6=1),0,IF($A$6=0,1,$A$6)*IF($B$6=0,1,$B$6)*IF($D$6=0,1,$D$6)) -> 0 | G6: =IF($E$1="","",$B$1&""&$E$1) | H6: Parent商品 | J6: =IF($G$1="","",$B$3&" "&$G$1) | M6: =IF(M$7="","",M$7) | N6: =M6 | O6: =IF(O$7="","",O$7) | P6: =IF(O6="","",IF($P$3="否",O6,O6&"cm")) | R6: SEO标题 | S6: Stop a TikTok shutdown TikTok changed my life for the better tshirt
R8: SEO描述 | S8: Congress is planning a total ban of TikTok. Speak up now-before your government strips 170 million America
R10: SEO关键词 | S10: Keep Tiktok Stop a TikTok shutdown tshirt shirt tee graphic novelty print printed cotton apparel clothing top men man women woman Pink Blue Grey Grey Green Black Grey Brown Purple Red Green Blue Red Blue
R12: SEO URL Handle
R14: 商品标签 | S14: Keep Tiktok Stop a TikTok shutdown, flag, take America back, men, women, Stop a TikTok shutdown,T-Shirt,Tshirt
R17: 商品描述
R19: <h3><strong>商品詳細説明</strong></h3> <p>このレディースビジネスシャツは、竹繊維（30%〜50%未満）とポリエステル（50%〜70%未満）のハイブリッド素材を使用し、通気性、速乾性、肌触りの良さを兼ね備えた一枚です。免烫・抗皺加工が施されているため、忙しい毎日でもアイロン要らずで、きれいなシルエットをキープできます。</p> <p>また、竹繊維特有の吸湿速乾機能により、汗をかいても素早く吸収・発散し、春夏シーズンでも爽やかな着心地を提供。シンプルなホワイトデザインは、オフィスやフォーマルな場面だけでなく、カジュアルコーデにも取り入れやすく、幅広いシーンで活躍します。</p> <p>S・M・L・XLの4サイズ展開で、体型やスタイルに合わせて選べるのもポイント。日常使いはもちろん、仕事用や出張時、会議などのビジネスシーンにもぴったりのシャツです。</p> <p>【仕様】</p> <ul> <li>素材：竹繊維 30%〜50%未満、ポリエステル 50%〜70%未満</li> <li>カラー：ホワイト</li> <li>サイズ展開：S / M / L / XL</li> <li>シーズン：春・夏</li> <li>スタイル：ビジネス、オフィスカジュアル、通勤、フォーマル</li> </ul> <p>【おすすめポイント】<br>✔️ 免烫・抗皺加工でアイロン不要！<br>✔️ 通気性・吸湿速乾機能で蒸れにくく快適！<br>✔️ シンプルで洗練されたデザイン、あらゆるシーンで活躍！<br>✔️ 豊富なサイズ展開で自分にぴったりのフィット感！</p>
C23: =IFERROR((VLOOKUP(B23,#REF!,2,FALSE)),"") | F23: =LENB(H23) -> 0 | G23: =IF(AND(0=$B$6,$A$5>0),IF($H23="","",$G$6&"-"&O23),IF(OR($H23="",$C$6=0),"",$G$6&"-"&VLOOKUP(M23,B:C,2,FALSE)&"-"&O23)) | H23: =IF(COUNTA($H$5:H22)-1<$E$6,"("&IF($A$6=0,"",INDIRECT("A"&MOD(ROW()-ROW($A$7),$A$6)+ROW($A$7)))&" "&IF($B$6=0,"",INDIRECT("B"&MOD(ROUNDUP((ROW()-ROW($B$7)+1)/$A$6,0)-1,$B$6)+ROW($A$7)))&" "&IF($D$6=0,"",INDIRECT("C"&MOD(ROUNDUP((ROW()-ROW($B$7)+1)/($E$6/$D$6),0)-1,$E$6)+ROW($A$7)))&")","") | I23: =IF(H23="","",COUNTIF($H$7:$H$105,H23)) | J23: =IF(OR(H23="",$G$1=""),"",$B$3&" "&$G$1&H23) | M23: =IF(OR($H23="",$B$6=0),"",INDIRECT("B"&MOD(ROUNDUP((ROW()-ROW($B$7)+1)/$A$6,0)-1,$B$6)+ROW($A$7))) | N23: =M23 | O23: =IF(H23="","",IF($A$6=0,"",INDIRECT("A"&MOD(ROW()-ROW($A$7),$A$6)+ROW($A$7)))) | P23: =IF(O23="","",IF($P$3="否",O23,O23&"cm"))
C24: =IFERROR((VLOOKUP(B24,#REF!,2,FALSE)),"") | F24: =LENB(H24) -> 0 | G24: =IF(AND(0=$B$6,$A$5>0),IF($H24="","",$G$6&"-"&O24),IF(OR($H24="",$C$6=0),"",$G$6&"-"&VLOOKUP(M24,B:C,2,FALSE)&"-"&O24)) | H24: =IF(COUNTA($H$5:H23)-1<$E$6,"("&IF($A$6=0,"",INDIRECT("A"&MOD(ROW()-ROW($A$7),$A$6)+ROW($A$7)))&" "&IF($B$6=0,"",INDIRECT("B"&MOD(ROUNDUP((ROW()-ROW($B$7)+1)/$A$6,0)-1,$B$6)+ROW($A$7)))&" "&IF($D$6=0,"",INDIRECT("C"&MOD(ROUNDUP((ROW()-ROW($B$7)+1)/($E$6/$D$6),0)-1,$E$6)+ROW($A$7)))&")","") | I24: =IF(H24="","",COUNTIF($H$7:$H$105,H24)) | J24: =IF(OR(H24="",$G$1=""),"",$B$3&" "&$G$1&H24) | M24: =IF(OR($H24="",$B$6=0),"",INDIRECT("B"&MOD(ROUNDUP((ROW()-ROW($B$7)+1)/$A$6,0)-1,$B$6)+ROW($A$7))) | N24: =M24 | O24: =IF(H24="","",IF($A$6=0,"",INDIRECT("A"&MOD(ROW()-ROW($A$7),$A$6)+ROW($A$7)))) | P24: =IF(O24="","",IF($P$3="否",O24,O24&"cm"))
C25: =IFERROR((VLOOKUP(B25,#REF!,2,FALSE)),"") | F25: =LENB(H25) -> 0 | G25: =IF(AND(0=$B$6,$A$5>0),IF($H25="","",$G$6&"-"&O25),IF(OR($H25="",$C$6=0),"",$G$6&"-"&VLOOKUP(M25,B:C,2,FALSE)&"-"&O25)) | H25: =IF(COUNTA($H$5:H24)-1<$E$6,"("&IF($A$6=0,"",INDIRECT("A"&MOD(ROW()-ROW($A$7),$A$6)+ROW($A$7)))&" "&IF($B$6=0,"",INDIRECT("B"&MOD(ROUNDUP((ROW()-ROW($B$7)+1)/$A$6,0)-1,$B$6)+ROW($A$7)))&" "&IF($D$6=0,"",INDIRECT("C"&MOD(ROUNDUP((ROW()-ROW($B$7)+1)/($E$6/$D$6),0)-1,$E$6)+ROW($A$7)))&")","") | I25: =IF(H25="","",COUNTIF($H$7:$H$105,H25)) | J25: =IF(OR(H25="",$G$1=""),"",$B$3&" "&$G$1&H25) | M25: =IF(OR($H25="",$B$6=0),"",INDIRECT("B"&MOD(ROUNDUP((ROW()-ROW($B$7)+1)/$A$6,0)-1,$B$6)+ROW($A$7))) | N25: =M25 | O25: =IF(H25="","",IF($A$6=0,"",INDIRECT("A"&MOD(ROW()-ROW($A$7),$A$6)+ROW($A$7)))) | P25: =IF(O25="","",IF($P$3="否",O25,O25&"cm"))
C26: =IFERROR((VLOOKUP(B26,#REF!,2,FALSE)),"") | F26: =LENB(H26) -> 0 | G26: =IF(AND(0=$B$6,$A$5>0),IF($H26="","",$G$6&"-"&O26),IF(OR($H26="",$C$6=0),"",$G$6&"-"&VLOOKUP(M26,B:C,2,FALSE)&"-"&O26)) | H26: =IF(COUNTA($H$5:H25)-1<$E$6,"("&IF($A$6=0,"",INDIRECT("A"&MOD(ROW()-ROW($A$7),$A$6)+ROW($A$7)))&" "&IF($B$6=0,"",INDIRECT("B"&MOD(ROUNDUP((ROW()-ROW($B$7)+1)/$A$6,0)-1,$B$6)+ROW($A$7)))&" "&IF($D$6=0,"",INDIRECT("C"&MOD(ROUNDUP((ROW()-ROW($B$7)+1)/($E$6/$D$6),0)-1,$E$6)+ROW($A$7)))&")","") | I26: =IF(H26="","",COUNTIF($H$7:$H$105,H26)) | J26: =IF(OR(H26="",$G$1=""),"",$B$3&" "&$G$1&H26) | M26: =IF(OR($H26="",$B$6=0),"",INDIRECT("B"&MOD(ROUNDUP((ROW()-ROW($B$7)+1)/$A$6,0)-1,$B$6)+ROW($A$7))) | N26: =M26 | O26: =IF(H26="","",IF($A$6=0,"",INDIRECT("A"&MOD(ROW()-ROW($A$7),$A$6)+ROW($A$7)))) | P26: =IF(O26="","",IF($P$3="否",O26,O26&"cm"))
C27: =IFERROR((VLOOKUP(B27,#REF!,2,FALSE)),"") | F27: =LENB(H27) -> 0 | G27: =IF(AND(0=$B$6,$A$5>0),IF($H27="","",$G$6&"-"&O27),IF(OR($H27="",$C$6=0),"",$G$6&"-"&VLOOKUP(M27,B:C,2,FALSE)&"-"&O27)) | H27: =IF(COUNTA($H$5:H26)-1<$E$6,"("&IF($A$6=0,"",INDIRECT("A"&MOD(ROW()-ROW($A$7),$A$6)+ROW($A$7)))&" "&IF($B$6=0,"",INDIRECT("B"&MOD(ROUNDUP((ROW()-ROW($B$7)+1)/$A$6,0)-1,$B$6)+ROW($A$7)))&" "&IF($D$6=0,"",INDIRECT("C"&MOD(ROUNDUP((ROW()-ROW($B$7)+1)/($E$6/$D$6),0)-1,$E$6)+ROW($A$7)))&")","") | I27: =IF(H27="","",COUNTIF($H$7:$H$105,H27)) | J27: =IF(OR(H27="",$G$1=""),"",$B$3&" "&$G$1&H27) | M27: =IF(OR($H27="",$B$6=0),"",INDIRECT("B"&MOD(ROUNDUP((ROW()-ROW($B$7)+1)/$A$6,0)-1,$B$6)+ROW($A$7))) | N27: =M27 | O27: =IF(H27="","",IF($A$6=0,"",INDIRECT("A"&MOD(ROW()-ROW($A$7),$A$6)+ROW($A$7)))) | P27: =IF(O27="","",IF($P$3="否",O27,O27&"cm"))
C28: =IFERROR((VLOOKUP(B28,#REF!,2,FALSE)),"") | F28: =LENB(H28) -> 0 | G28: =IF(AND(0=$B$6,$A$5>0),IF($H28="","",$G$6&"-"&O28),IF(OR($H28="",$C$6=0),"",$G$6&"-"&VLOOKUP(M28,B:C,2,FALSE)&"-"&O28)) | H28: =IF(COUNTA($H$5:H27)-1<$E$6,"("&IF($A$6=0,"",INDIRECT("A"&MOD(ROW()-ROW($A$7),$A$6)+ROW($A$7)))&" "&IF($B$6=0,"",INDIRECT("B"&MOD(ROUNDUP((ROW()-ROW($B$7)+1)/$A$6,0)-1,$B$6)+ROW($A$7)))&" "&IF($D$6=0,"",INDIRECT("C"&MOD(ROUNDUP((ROW()-ROW($B$7)+1)/($E$6/$D$6),0)-1,$E$6)+ROW($A$7)))&")","") | I28: =IF(H28="","",COUNTIF($H$7:$H$105,H28)) | J28: =IF(OR(H28="",$G$1=""),"",$B$3&" "&$G$1&H28) | M28: =IF(OR($H28="",$B$6=0),"",INDIRECT("B"&MOD(ROUNDUP((ROW()-ROW($B$7)+1)/$A$6,0)-1,$B$6)+ROW($A$7))) | N28: =M28 | O28: =IF(H28="","",IF($A$6=0,"",INDIRECT("A"&MOD(ROW()-ROW($A$7),$A$6)+ROW($A$7)))) | P28: =IF(O28="","",IF($P$3="否",O28,O28&"cm"))
C29: =IFERROR((VLOOKUP(B29,#REF!,2,FALSE)),"") | F29: =LENB(H29) -> 0 | G29: =IF(AND(0=$B$6,$A$5>0),IF($H29="","",$G$6&"-"&O29),IF(OR($H29="",$C$6=0),"",$G$6&"-"&VLOOKUP(M29,B:C,2,FALSE)&"-"&O29)) | H29: =IF(COUNTA($H$5:H28)-1<$E$6,"("&IF($A$6=0,"",INDIRECT("A"&MOD(ROW()-ROW($A$7),$A$6)+ROW($A$7)))&" "&IF($B$6=0,"",INDIRECT("B"&MOD(ROUNDUP((ROW()-ROW($B$7)+1)/$A$6,0)-1,$B$6)+ROW($A$7)))&" "&IF($D$6=0,"",INDIRECT("C"&MOD(ROUNDUP((ROW()-ROW($B$7)+1)/($E$6/$D$6),0)-1,$E$6)+ROW($A$7)))&")","") | I29: =IF(H29="","",COUNTIF($H$7:$H$105,H29)) | J29: =IF(OR(H29="",$G$1=""),"",$B$3&" "&$G$1&H29) | M29: =IF(OR($H29="",$B$6=0),"",INDIRECT("B"&MOD(ROUNDUP((ROW()-ROW($B$7)+1)/$A$6,0)-1,$B$6)+ROW($A$7))) | N29: =M29 | O29: =IF(H29="","",IF($A$6=0,"",INDIRECT("A"&MOD(ROW()-ROW($A$7),$A$6)+ROW($A$7)))) | P29: =IF(O29="","",IF($P$3="否",O29,O29&"cm")) | R29: 参数表
C30: =IFERROR((VLOOKUP(B30,#REF!,2,FALSE)),"") | F30: =LENB(H30) -> 0 | G30: =IF(AND(0=$B$6,$A$5>0),IF($H30="","",$G$6&"-"&O30),IF(OR($H30="",$C$6=0),"",$G$6&"-"&VLOOKUP(M30,B:C,2,FALSE)&"-"&O30)) | H30: =IF(COUNTA($H$5:H29)-1<$E$6,"("&IF($A$6=0,"",INDIRECT("A"&MOD(ROW()-ROW($A$7),$A$6)+ROW($A$7)))&" "&IF($B$6=0,"",INDIRECT("B"&MOD(ROUNDUP((ROW()-ROW($B$7)+1)/$A$6,0)-1,$B$6)+ROW($A$7)))&" "&IF($D$6=0,"",INDIRECT("C"&MOD(ROUNDUP((ROW()-ROW($B$7)+1)/($E$6/$D$6),0)-1,$E$6)+ROW($A$7)))&")","") | I30: =IF(H30="","",COUNTIF($H$7:$H$105,H30)) | J30: =IF(OR(H30="",$G$1=""),"",$B$3&" "&$G$1&H30) | M30: =IF(OR($H30="",$B$6=0),"",INDIRECT("B"&MOD(ROUNDUP((ROW()-ROW($B$7)+1)/$A$6,0)-1,$B$6)+ROW($A$7))) | N30: =M30 | O30: =IF(H30="","",IF($A$6=0,"",INDIRECT("A"&MOD(ROW()-ROW($A$7),$A$6)+ROW($A$7)))) | P30: =IF(O30="","",IF($P$3="否",O30,O30&"cm")) | R30: 商品重量 | T30: 0.3
C31: =IFERROR((VLOOKUP(B31,#REF!,2,FALSE)),"") | F31: =LENB(H31) -> 0 | G31: =IF(AND(0=$B$6,$A$5>0),IF($H31="","",$G$6&"-"&O31),IF(OR($H31="",$C$6=0),"",$G$6&"-"&VLOOKUP(M31,B:C,2,FALSE)&"-"&O31)) | H31: =IF(COUNTA($H$5:H30)-1<$E$6,"("&IF($A$6=0,"",INDIRECT("A"&MOD(ROW()-ROW($A$7),$A$6)+ROW($A$7)))&" "&IF($B$6=0,"",INDIRECT("B"&MOD(ROUNDUP((ROW()-ROW($B$7)+1)/$A$6,0)-1,$B$6)+ROW($A$7)))&" "&IF($D$6=0,"",INDIRECT("C"&MOD(ROUNDUP((ROW()-ROW($B$7)+1)/($E$6/$D$6),0)-1,$E$6)+ROW($A$7)))&")","") | I31: =IF(H31="","",COUNTIF($H$7:$H$105,H31)) | J31: =IF(OR(H31="",$G$1=""),"",$B$3&" "&$G$1&H31) | M31: =IF(OR($H31="",$B$6=0),"",INDIRECT("B"&MOD(ROUNDUP((ROW()-ROW($B$7)+1)/$A$6,0)-1,$B$6)+ROW($A$7))) | N31: =M31 | O31: =IF(H31="","",IF($A$6=0,"",INDIRECT("A"&MOD(ROW()-ROW($A$7),$A$6)+ROW($A$7)))) | P31: =IF(O31="","",IF($P$3="否",O31,O31&"cm")) | R31: 商品库存 | T31: 2000
C32: =IFERROR((VLOOKUP(B32,#REF!,2,FALSE)),"") | F32: =LENB(H32) -> 0 | G32: =IF(AND(0=$B$6,$A$5>0),IF($H32="","",$G$6&"-"&O32),IF(OR($H32="",$C$6=0),"",$G$6&"-"&VLOOKUP(M32,B:C,2,FALSE)&"-"&O32)) | H32: =IF(COUNTA($H$5:H31)-1<$E$6,"("&IF($A$6=0,"",INDIRECT("A"&MOD(ROW()-ROW($A$7),$A$6)+ROW($A$7)))&" "&IF($B$6=0,"",INDIRECT("B"&MOD(ROUNDUP((ROW()-ROW($B$7)+1)/$A$6,0)-1,$B$6)+ROW($A$7)))&" "&IF($D$6=0,"",INDIRECT("C"&MOD(ROUNDUP((ROW()-ROW($B$7)+1)/($E$6/$D$6),0)-1,$E$6)+ROW($A$7)))&")","") | I32: =IF(H32="","",COUNTIF($H$7:$H$105,H32)) | J32: =IF(OR(H32="",$G$1=""),"",$B$3&" "&$G$1&H32) | M32: =IF(OR($H32="",$B$6=0),"",INDIRECT("B"&MOD(ROUNDUP((ROW()-ROW($B$7)+1)/$A$6,0)-1,$B$6)+ROW($A$7))) | N32: =M32 | O32: =IF(H32="","",IF($A$6=0,"",INDIRECT("A"&MOD(ROW()-ROW($A$7),$A$6)+ROW($A$7)))) | P32: =IF(O32="","",IF($P$3="否",O32,O32&"cm")) | R32: 供应商名称 | T32: XMLeKe
C33: =IFERROR((VLOOKUP(B33,#REF!,2,FALSE)),"") | F33: =LENB(H33) -> 0 | G33: =IF(AND(0=$B$6,$A$5>0),IF($H33="","",$G$6&"-"&O33),IF(OR($H33="",$C$6=0),"",$G$6&"-"&VLOOKUP(M33,B:C,2,FALSE)&"-"&O33)) | H33: =IF(COUNTA($H$5:H32)-1<$E$6,"("&IF($A$6=0,"",INDIRECT("A"&MOD(ROW()-ROW($A$7),$A$6)+ROW($A$7)))&" "&IF($B$6=0,"",INDIRECT("B"&MOD(ROUNDUP((ROW()-ROW($B$7)+1)/$A$6,0)-1,$B$6)+ROW($A$7)))&" "&IF($D$6=0,"",INDIRECT("C"&MOD(ROUNDUP((ROW()-ROW($B$7)+1)/($E$6/$D$6),0)-1,$E$6)+ROW($A$7)))&")","") | I33: =IF(H33="","",COUNTIF($H$7:$H$105,H33)) | J33: =IF(OR(H33="",$G$1=""),"",$B$3&" "&$G$1&H33) | M33: =IF(OR($H33="",$B$6=0),"",INDIRECT("B"&MOD(ROUNDUP((ROW()-ROW($B$7)+1)/$A$6,0)-1,$B$6)+ROW($A$7))) | N33: =M33 | O33: =IF(H33="","",IF($A$6=0,"",INDIRECT("A"&MOD(ROW()-ROW($A$7),$A$6)+ROW($A$7)))) | P33: =IF(O33="","",IF($P$3="否",O33,O33&"cm")) | R33: 供应商链接 | T33: https://detail.1688.com/offer/695456185594.html?spm=a261y.7663282.module-desc.10.7a7e1b09WZk867
C34: =IFERROR((VLOOKUP(B34,#REF!,2,FALSE)),"") | F34: =LENB(H34) -> 0 | G34: =IF(AND(0=$B$6,$A$5>0),IF($H34="","",$G$6&"-"&O34),IF(OR($H34="",$C$6=0),"",$G$6&"-"&VLOOKUP(M34,B:C,2,FALSE)&"-"&O34)) | H34: =IF(COUNTA($H$5:H33)-1<$E$6,"("&IF($A$6=0,"",INDIRECT("A"&MOD(ROW()-ROW($A$7),$A$6)+ROW($A$7)))&" "&IF($B$6=0,"",INDIRECT("B"&MOD(ROUNDUP((ROW()-ROW($B$7)+1)/$A$6,0)-1,$B$6)+ROW($A$7)))&" "&IF($D$6=0,"",INDIRECT("C"&MOD(ROUNDUP((ROW()-ROW($B$7)+1)/($E$6/$D$6),0)-1,$E$6)+ROW($A$7)))&")","") | I34: =IF(H34="","",COUNTIF($H$7:$H$105,H34)) | J34: =IF(OR(H34="",$G$1=""),"",$B$3&" "&$G$1&H34) | M34: =IF(OR($H34="",$B$6=0),"",INDIRECT("B"&MOD(ROUNDUP((ROW()-ROW($B$7)+1)/$A$6,0)-1,$B$6)+ROW($A$7))) | N34: =M34 | O34: =IF(H34="","",IF($A$6=0,"",INDIRECT("A"&MOD(ROW()-ROW($A$7),$A$6)+ROW($A$7)))) | P34: =IF(O34="","",IF($P$3="否",O34,O34&"cm")) | R34: 专辑名称 | T34: HotTopicTshirts
C35: =IFERROR((VLOOKUP(B35,#REF!,2,FALSE)),"") | F35: =LENB(H35) -> 0 | G35: =IF(AND(0=$B$6,$A$5>0),IF($H35="","",$G$6&"-"&O35),IF(OR($H35="",$C$6=0),"",$G$6&"-"&VLOOKUP(M35,B:C,2,FALSE)&"-"&O35)) | H35: =IF(COUNTA($H$5:H34)-1<$E$6,"("&IF($A$6=0,"",INDIRECT("A"&MOD(ROW()-ROW($A$7),$A$6)+ROW($A$7)))&" "&IF($B$6=0,"",INDIRECT("B"&MOD(ROUNDUP((ROW()-ROW($B$7)+1)/$A$6,0)-1,$B$6)+ROW($A$7)))&" "&IF($D$6=0,"",INDIRECT("C"&MOD(ROUNDUP((ROW()-ROW($B$7)+1)/($E$6/$D$6),0)-1,$E$6)+ROW($A$7)))&")","") | I35: =IF(H35="","",COUNTIF($H$7:$H$105,H35)) | J35: =IF(OR(H35="",$G$1=""),"",$B$3&" "&$G$1&H35) | M35: =IF(OR($H35="",$B$6=0),"",INDIRECT("B"&MOD(ROUNDUP((ROW()-ROW($B$7)+1)/$A$6,0)-1,$B$6)+ROW($A$7))) | N35: =M35 | O35: =IF(H35="","",IF($A$6=0,"",INDIRECT("A"&MOD(ROW()-ROW($A$7),$A$6)+ROW($A$7)))) | P35: =IF(O35="","",IF($P$3="否",O35,O35&"cm")) | R35: 虚拟销量 | T35: 566
C36: =IFERROR((VLOOKUP(B36,#REF!,2,FALSE)),"") | F36: =LENB(H36) -> 0 | G36: =IF(AND(0=$B$6,$A$5>0),IF($H36="","",$G$6&"-"&O36),IF(OR($H36="",$C$6=0),"",$G$6&"-"&VLOOKUP(M36,B:C,2,FALSE)&"-"&O36)) | H36: =IF(COUNTA($H$5:H35)-1<$E$6,"("&IF($A$6=0,"",INDIRECT("A"&MOD(ROW()-ROW($A$7),$A$6)+ROW($A$7)))&" "&IF($B$6=0,"",INDIRECT("B"&MOD(ROUNDUP((ROW()-ROW($B$7)+1)/$A$6,0)-1,$B$6)+ROW($A$7)))&" "&IF($D$6=0,"",INDIRECT("C"&MOD(ROUNDUP((ROW()-ROW($B$7)+1)/($E$6/$D$6),0)-1,$E$6)+ROW($A$7)))&")","") | I36: =IF(H36="","",COUNTIF($H$7:$H$105,H36)) | J36: =IF(OR(H36="",$G$1=""),"",$B$3&" "&$G$1&H36) | M36: =IF(OR($H36="",$B$6=0),"",INDIRECT("B"&MOD(ROUNDUP((ROW()-ROW($B$7)+1)/$A$6,0)-1,$B$6)+ROW($A$7))) | N36: =M36 | O36: =IF(H36="","",IF($A$6=0,"",INDIRECT("A"&MOD(ROW()-ROW($A$7),$A$6)+ROW($A$7)))) | P36: =IF(O36="","",IF($P$3="否",O36,O36&"cm")) | R36: variation_theme | T36: color-size
C37: =IFERROR((VLOOKUP(B37,#REF!,2,FALSE)),"") | F37: =LENB(H37) -> 0 | G37: =IF(AND(0=$B$6,$A$5>0),IF($H37="","",$G$6&"-"&O37),IF(OR($H37="",$C$6=0),"",$G$6&"-"&VLOOKUP(M37,B:C,2,FALSE)&"-"&O37)) | H37: =IF(COUNTA($H$5:H36)-1<$E$6,"("&IF($A$6=0,"",INDIRECT("A"&MOD(ROW()-ROW($A$7),$A$6)+ROW($A$7)))&" "&IF($B$6=0,"",INDIRECT("B"&MOD(ROUNDUP((ROW()-ROW($B$7)+1)/$A$6,0)-1,$B$6)+ROW($A$7)))&" "&IF($D$6=0,"",INDIRECT("C"&MOD(ROUNDUP((ROW()-ROW($B$7)+1)/($E$6/$D$6),0)-1,$E$6)+ROW($A$7)))&")","") | I37: =IF(H37="","",COUNTIF($H$7:$H$105,H37)) | J37: =IF(OR(H37="",$G$1=""),"",$B$3&" "&$G$1&H37) | M37: =IF(OR($H37="",$B$6=0),"",INDIRECT("B"&MOD(ROUNDUP((ROW()-ROW($B$7)+1)/$A$6,0)-1,$B$6)+ROW($A$7))) | N37: =M37 | O37: =IF(H37="","",IF($A$6=0,"",INDIRECT("A"&MOD(ROW()-ROW($A$7),$A$6)+ROW($A$7)))) | P37: =IF(O37="","",IF($P$3="否",O37,O37&"cm")) | R37: 材料fabric_type | T37: 90% Cotton, 10% Polyester
C38: =IFERROR((VLOOKUP(B38,#REF!,2,FALSE)),"") | F38: =LENB(H38) -> 0 | G38: =IF(AND(0=$B$6,$A$5>0),IF($H38="","",$G$6&"-"&O38),IF(OR($H38="",$C$6=0),"",$G$6&"-"&VLOOKUP(M38,B:C,2,FALSE)&"-"&O38)) | H38: =IF(COUNTA($H$5:H37)-1<$E$6,"("&IF($A$6=0,"",INDIRECT("A"&MOD(ROW()-ROW($A$7),$A$6)+ROW($A$7)))&" "&IF($B$6=0,"",INDIRECT("B"&MOD(ROUNDUP((ROW()-ROW($B$7)+1)/$A$6,0)-1,$B$6)+ROW($A$7)))&" "&IF($D$6=0,"",INDIRECT("C"&MOD(ROUNDUP((ROW()-ROW($B$7)+1)/($E$6/$D$6),0)-1,$E$6)+ROW($A$7)))&")","") | I38: =IF(H38="","",COUNTIF($H$7:$H$105,H38)) | J38: =IF(OR(H38="",$G$1=""),"",$B$3&" "&$G$1&H38) | M38: =IF(OR($H38="",$B$6=0),"",INDIRECT("B"&MOD(ROUNDUP((ROW()-ROW($B$7)+1)/$A$6,0)-1,$B$6)+ROW($A$7))) | N38: =M38 | O38: =IF(H38="","",IF($A$6=0,"",INDIRECT("A"&MOD(ROW()-ROW($A$7),$A$6)+ROW($A$7)))) | P38: =IF(O38="","",IF($P$3="否",O38,O38&"cm"))
C39: =IFERROR((VLOOKUP(B39,#REF!,2,FALSE)),"") | F39: =LENB(H39) -> 0 | G39: =IF(AND(0=$B$6,$A$5>0),IF($H39="","",$G$6&"-"&O39),IF(OR($H39="",$C$6=0),"",$G$6&"-"&VLOOKUP(M39,B:C,2,FALSE)&"-"&O39)) | H39: =IF(COUNTA($H$5:H38)-1<$E$6,"("&IF($A$6=0,"",INDIRECT("A"&MOD(ROW()-ROW($A$7),$A$6)+ROW($A$7)))&" "&IF($B$6=0,"",INDIRECT("B"&MOD(ROUNDUP((ROW()-ROW($B$7)+1)/$A$6,0)-1,$B$6)+ROW($A$7)))&" "&IF($D$6=0,"",INDIRECT("C"&MOD(ROUNDUP((ROW()-ROW($B$7)+1)/($E$6/$D$6),0)-1,$E$6)+ROW($A$7)))&")","") | I39: =IF(H39="","",COUNTIF($H$7:$H$105,H39)) | J39: =IF(OR(H39="",$G$1=""),"",$B$3&" "&$G$1&H39) | M39: =IF(OR($H39="",$B$6=0),"",INDIRECT("B"&MOD(ROUNDUP((ROW()-ROW($B$7)+1)/$A$6,0)-1,$B$6)+ROW($A$7))) | N39: =M39 | O39: =IF(H39="","",IF($A$6=0,"",INDIRECT("A"&MOD(ROW()-ROW($A$7),$A$6)+ROW($A$7)))) | P39: =IF(O39="","",IF($P$3="否",O39,O39&"cm")) | R39: 五点描述
C40: =IFERROR((VLOOKUP(B40,#REF!,2,FALSE)),"") | F40: =LENB(H40) -> 0 | G40: =IF(AND(0=$B$6,$A$5>0),IF($H40="","",$G$6&"-"&O40),IF(OR($H40="",$C$6=0),"",$G$6&"-"&VLOOKUP(M40,B:C,2,FALSE)&"-"&O40)) | H40: =IF(COUNTA($H$5:H39)-1<$E$6,"("&IF($A$6=0,"",INDIRECT("A"&MOD(ROW()-ROW($A$7),$A$6)+ROW($A$7)))&" "&IF($B$6=0,"",INDIRECT("B"&MOD(ROUNDUP((ROW()-ROW($B$7)+1)/$A$6,0)-1,$B$6)+ROW($A$7)))&" "&IF($D$6=0,"",INDIRECT("C"&MOD(ROUNDUP((ROW()-ROW($B$7)+1)/($E$6/$D$6),0)-1,$E$6)+ROW($A$7)))&")","") | I40: =IF(H40="","",COUNTIF($H$7:$H$105,H40)) | J40: =IF(OR(H40="",$G$1=""),"",$B$3&" "&$G$1&H40) | M40: =IF(OR($H40="",$B$6=0),"",INDIRECT("B"&MOD(ROUNDUP((ROW()-ROW($B$7)+1)/$A$6,0)-1,$B$6)+ROW($A$7))) | N40: =M40 | O40: =IF(H40="","",IF($A$6=0,"",INDIRECT("A"&MOD(ROW()-ROW($A$7),$A$6)+ROW($A$7)))) | P40: =IF(O40="","",IF($P$3="否",O40,O40&"cm"))
C41: =IFERROR((VLOOKUP(B41,#REF!,2,FALSE)),"") | F41: =LENB(H41) -> 0 | G41: =IF(AND(0=$B$6,$A$5>0),IF($H41="","",$G$6&"-"&O41),IF(OR($H41="",$C$6=0),"",$G$6&"-"&VLOOKUP(M41,B:C,2,FALSE)&"-"&O41)) | H41: =IF(COUNTA($H$5:H40)-1<$E$6,"("&IF($A$6=0,"",INDIRECT("A"&MOD(ROW()-ROW($A$7),$A$6)+ROW($A$7)))&" "&IF($B$6=0,"",INDIRECT("B"&MOD(ROUNDUP((ROW()-ROW($B$7)+1)/$A$6,0)-1,$B$6)+ROW($A$7)))&" "&IF($D$6=0,"",INDIRECT("C"&MOD(ROUNDUP((ROW()-ROW($B$7)+1)/($E$6/$D$6),0)-1,$E$6)+ROW($A$7)))&")","") | I41: =IF(H41="","",COUNTIF($H$7:$H$105,H41)) | J41: =IF(OR(H41="",$G$1=""),"",$B$3&" "&$G$1&H41) | M41: =IF(OR($H41="",$B$6=0),"",INDIRECT("B"&MOD(ROUNDUP((ROW()-ROW($B$7)+1)/$A$6,0)-1,$B$6)+ROW($A$7))) | N41: =M41 | O41: =IF(H41="","",IF($A$6=0,"",INDIRECT("A"&MOD(ROW()-ROW($A$7),$A$6)+ROW($A$7)))) | P41: =IF(O41="","",IF($P$3="否",O41,O41&"cm")) | R41: bullet_point1 | S41: 【竹繊維×ポリエステルの高機能素材】天然の竹繊維（30%〜50%未満）とポリエステル（50%〜70%未満）の組み合わせにより、通気性・吸湿性・速乾性を実現。長時間着ても快適で、肌触りも柔らか。デスクワークや通勤時にも爽やかな着心地を提供します。春夏は通気性が良くさらっと快適、秋冬はインナーとしても暖かく着られる万能アイテム。1年中活躍する通勤＆フォーマルシャツです。
C42: =IFERROR((VLOOKUP(B42,#REF!,2,FALSE)),"") | F42: =LENB(H42) -> 0 | G42: =IF(AND(0=$B$6,$A$5>0),IF($H42="","",$G$6&"-"&O42),IF(OR($H42="",$C$6=0),"",$G$6&"-"&VLOOKUP(M42,B:C,2,FALSE)&"-"&O42)) | H42: =IF(COUNTA($H$5:H41)-1<$E$6,"("&IF($A$6=0,"",INDIRECT("A"&MOD(ROW()-ROW($A$7),$A$6)+ROW($A$7)))&" "&IF($B$6=0,"",INDIRECT("B"&MOD(ROUNDUP((ROW()-ROW($B$7)+1)/$A$6,0)-1,$B$6)+ROW($A$7)))&" "&IF($D$6=0,"",INDIRECT("C"&MOD(ROUNDUP((ROW()-ROW($B$7)+1)/($E$6/$D$6),0)-1,$E$6)+ROW($A$7)))&")","") | I42: =IF(H42="","",COUNTIF($H$7:$H$105,H42)) | J42: =IF(OR(H42="",$G$1=""),"",$B$3&" "&$G$1&H42) | M42: =IF(OR($H42="",$B$6=0),"",INDIRECT("B"&MOD(ROUNDUP((ROW()-ROW($B$7)+1)/$A$6,0)-1,$B$6)+ROW($A$7))) | N42: =M42 | O42: =IF(H42="","",IF($A$6=0,"",INDIRECT("A"&MOD(ROW()-ROW($A$7),$A$6)+ROW($A$7)))) | P42: =IF(O42="","",IF($P$3="否",O42,O42&"cm"))
C43: =IFERROR((VLOOKUP(B43,#REF!,2,FALSE)),"") | F43: =LENB(H43) -> 0 | G43: =IF(AND(0=$B$6,$A$5>0),IF($H43="","",$G$6&"-"&O43),IF(OR($H43="",$C$6=0),"",$G$6&"-"&VLOOKUP(M43,B:C,2,FALSE)&"-"&O43)) | H43: =IF(COUNTA($H$5:H42)-1<$E$6,"("&IF($A$6=0,"",INDIRECT("A"&MOD(ROW()-ROW($A$7),$A$6)+ROW($A$7)))&" "&IF($B$6=0,"",INDIRECT("B"&MOD(ROUNDUP((ROW()-ROW($B$7)+1)/$A$6,0)-1,$B$6)+ROW($A$7)))&" "&IF($D$6=0,"",INDIRECT("C"&MOD(ROUNDUP((ROW()-ROW($B$7)+1)/($E$6/$D$6),0)-1,$E$6)+ROW($A$7)))&")","") | I43: =IF(H43="","",COUNTIF($H$7:$H$105,H43)) | J43: =IF(OR(H43="",$G$1=""),"",$B$3&" "&$G$1&H43) | M43: =IF(OR($H43="",$B$6=0),"",INDIRECT("B"&MOD(ROUNDUP((ROW()-ROW($B$7)+1)/$A$6,0)-1,$B$6)+ROW($A$7))) | N43: =M43 | O43: =IF(H43="","",IF($A$6=0,"",INDIRECT("A"&MOD(ROW()-ROW($A$7),$A$6)+ROW($A$7)))) | P43: =IF(O43="","",IF($P$3="否",O43,O43&"cm")) | R43: bullet_point2 | S43: 【免烫＆抗皺加工でお手入れ簡単】アイロン不要の免烫加工を施し、シワになりにくい仕様。忙しい朝でもサッと着用でき、仕事や会議でも常に清潔感のある印象を保てます。オフィスワークや出張にも最適です。
C44: =IFERROR((VLOOKUP(B44,#REF!,2,FALSE)),"") | F44: =LENB(H44) -> 0 | G44: =IF(AND(0=$B$6,$A$5>0),IF($H44="","",$G$6&"-"&O44),IF(OR($H44="",$C$6=0),"",$G$6&"-"&VLOOKUP(M44,B:C,2,FALSE)&"-"&O44)) | H44: =IF(COUNTA($H$5:H43)-1<$E$6,"("&IF($A$6=0,"",INDIRECT("A"&MOD(ROW()-ROW($A$7),$A$6)+ROW($A$7)))&" "&IF($B$6=0,"",INDIRECT("B"&MOD(ROUNDUP((ROW()-ROW($B$7)+1)/$A$6,0)-1,$B$6)+ROW($A$7)))&" "&IF($D$6=0,"",INDIRECT("C"&MOD(ROUNDUP((ROW()-ROW($B$7)+1)/($E$6/$D$6),0)-1,$E$6)+ROW($A$7)))&")","") | I44: =IF(H44="","",COUNTIF($H$7:$H$105,H44)) | J44: =IF(OR(H44="",$G$1=""),"",$B$3&" "&$G$1&H44) | M44: =IF(OR($H44="",$B$6=0),"",INDIRECT("B"&MOD(ROUNDUP((ROW()-ROW($B$7)+1)/$A$6,0)-1,$B$6)+ROW($A$7))) | N44: =M44 | O44: =IF(H44="","",IF($A$6=0,"",INDIRECT("A"&MOD(ROW()-ROW($A$7),$A$6)+ROW($A$7)))) | P44: =IF(O44="","",IF($P$3="否",O44,O44&"cm"))
C45: =IFERROR((VLOOKUP(B45,#REF!,2,FALSE)),"") | F45: =LENB(H45) -> 0 | G45: =IF(AND(0=$B$6,$A$5>0),IF($H45="","",$G$6&"-"&O45),IF(OR($H45="",$C$6=0),"",$G$6&"-"&VLOOKUP(M45,B:C,2,FALSE)&"-"&O45)) | H45: =IF(COUNTA($H$5:H44)-1<$E$6,"("&IF($A$6=0,"",INDIRECT("A"&MOD(ROW()-ROW($A$7),$A$6)+ROW($A$7)))&" "&IF($B$6=0,"",INDIRECT("B"&MOD(ROUNDUP((ROW()-ROW($B$7)+1)/$A$6,0)-1,$B$6)+ROW($A$7)))&" "&IF($D$6=0,"",INDIRECT("C"&MOD(ROUNDUP((ROW()-ROW($B$7)+1)/($E$6/$D$6),0)-1,$E$6)+ROW($A$7)))&")","") | I45: =IF(H45="","",COUNTIF($H$7:$H$105,H45)) | J45: =IF(OR(H45="",$G$1=""),"",$B$3&" "&$G$1&H45) | M45: =IF(OR($H45="",$B$6=0),"",INDIRECT("B"&MOD(ROUNDUP((ROW()-ROW($B$7)+1)/$A$6,0)-1,$B$6)+ROW($A$7))) | N45: =M45 | O45: =IF(H45="","",IF($A$6=0,"",INDIRECT("A"&MOD(ROW()-ROW($A$7),$A$6)+ROW($A$7)))) | P45: =IF(O45="","",IF($P$3="否",O45,O45&"cm")) | R45: bullet_point3 | S45: 【吸湿速乾＆通気性抜群で快適】竹繊維特有の吸湿速乾機能が汗を素早く吸収・発散し、長時間の着用でも快適。通気性に優れ、春夏の暑い季節でもサラリとした着心地を実現。蒸し暑い日や電車通勤時もベタつきを抑えます。
C46: =IFERROR((VLOOKUP(B46,#REF!,2,FALSE)),"") | F46: =LENB(H46) -> 0 | G46: =IF(AND(0=$B$6,$A$5>0),IF($H46="","",$G$6&"-"&O46),IF(OR($H46="",$C$6=0),"",$G$6&"-"&VLOOKUP(M46,B:C,2,FALSE)&"-"&O46)) | H46: =IF(COUNTA($H$5:H45)-1<$E$6,"("&IF($A$6=0,"",INDIRECT("A"&MOD(ROW()-ROW($A$7),$A$6)+ROW($A$7)))&" "&IF($B$6=0,"",INDIRECT("B"&MOD(ROUNDUP((ROW()-ROW($B$7)+1)/$A$6,0)-1,$B$6)+ROW($A$7)))&" "&IF($D$6=0,"",INDIRECT("C"&MOD(ROUNDUP((ROW()-ROW($B$7)+1)/($E$6/$D$6),0)-1,$E$6)+ROW($A$7)))&")","") | I46: =IF(H46="","",COUNTIF($H$7:$H$105,H46)) | J46: =IF(OR(H46="",$G$1=""),"",$B$3&" "&$G$1&H46) | M46: =IF(OR($H46="",$B$6=0),"",INDIRECT("B"&MOD(ROUNDUP((ROW()-ROW($B$7)+1)/$A$6,0)-1,$B$6)+ROW($A$7))) | N46: =M46 | O46: =IF(H46="","",IF($A$6=0,"",INDIRECT("A"&MOD(ROW()-ROW($A$7),$A$6)+ROW($A$7)))) | P46: =IF(O46="","",IF($P$3="否",O46,O46&"cm"))
C47: =IFERROR((VLOOKUP(B47,#REF!,2,FALSE)),"") | F47: =LENB(H47) -> 0 | G47: =IF(AND(0=$B$6,$A$5>0),IF($H47="","",$G$6&"-"&O47),IF(OR($H47="",$C$6=0),"",$G$6&"-"&VLOOKUP(M47,B:C,2,FALSE)&"-"&O47)) | H47: =IF(COUNTA($H$5:H46)-1<$E$6,"("&IF($A$6=0,"",INDIRECT("A"&MOD(ROW()-ROW($A$7),$A$6)+ROW($A$7)))&" "&IF($B$6=0,"",INDIRECT("B"&MOD(ROUNDUP((ROW()-ROW($B$7)+1)/$A$6,0)-1,$B$6)+ROW($A$7)))&" "&IF($D$6=0,"",INDIRECT("C"&MOD(ROUNDUP((ROW()-ROW($B$7)+1)/($E$6/$D$6),0)-1,$E$6)+ROW($A$7)))&")","") | I47: =IF(H47="","",COUNTIF($H$7:$H$105,H47)) | J47: =IF(OR(H47="",$G$1=""),"",$B$3&$G$1&H47) | M47: =IF(OR($H47="",$B$6=0),"",INDIRECT("B"&MOD(ROUNDUP((ROW()-ROW($B$7)+1)/$A$6,0)-1,$B$6)+ROW($A$7))) | N47: =M47 | O47: =IF(H47="","",IF($A$6=0,"",INDIRECT("A"&MOD(ROW()-ROW($A$7),$A$6)+ROW($A$7)))) | P47: =IF(O47="","",IF($P$3="否",O47,O47&"cm")) | R47: bullet_point4 | S47: 【シンプル＆上品なデザイン、4色展開】ベーシックで洗練されたデザインのホワイト、ブラック、グレー、天ブルーの4色展開。シーンに合わせて選べるカラーバリエーションで、オフィス・カジュアル・フォーマルなど幅広く活躍。スーツのインナーとしても相性抜群！
C48: =IFERROR((VLOOKUP(B48,#REF!,2,FALSE)),"") | F48: =LENB(H48) -> 0 | G48: =IF(AND(0=$B$6,$A$5>0),IF($H48="","",$G$6&"-"&O48),IF(OR($H48="",$C$6=0),"",$G$6&"-"&VLOOKUP(M48,B:C,2,FALSE)&"-"&O48)) | H48: =IF(COUNTA($H$5:H47)-1<$E$6,"("&IF($A$6=0,"",INDIRECT("A"&MOD(ROW()-ROW($A$7),$A$6)+ROW($A$7)))&" "&IF($B$6=0,"",INDIRECT("B"&MOD(ROUNDUP((ROW()-ROW($B$7)+1)/$A$6,0)-1,$B$6)+ROW($A$7)))&" "&IF($D$6=0,"",INDIRECT("C"&MOD(ROUNDUP((ROW()-ROW($B$7)+1)/($E$6/$D$6),0)-1,$E$6)+ROW($A$7)))&")","") | I48: =IF(H48="","",COUNTIF($H$7:$H$105,H48)) | J48: =IF(OR(H48="",$G$1=""),"",$B$3&$G$1&H48) | M48: =IF(OR($H48="",$B$6=0),"",INDIRECT("B"&MOD(ROUNDUP((ROW()-ROW($B$7)+1)/$A$6,0)-1,$B$6)+ROW($A$7))) | N48: =M48 | O48: =IF(H48="","",IF($A$6=0,"",INDIRECT("A"&MOD(ROW()-ROW($A$7),$A$6)+ROW($A$7)))) | P48: =IF(O48="","",IF($P$3="否",O48,O48&"cm"))
C49: =IFERROR((VLOOKUP(B49,#REF!,2,FALSE)),"") | F49: =LENB(H49) -> 0 | G49: =IF(AND(0=$B$6,$A$5>0),IF($H49="","",$G$6&"-"&O49),IF(OR($H49="",$C$6=0),"",$G$6&"-"&VLOOKUP(M49,B:C,2,FALSE)&"-"&O49)) | H49: =IF(COUNTA($H$5:H48)-1<$E$6,"("&IF($A$6=0,"",INDIRECT("A"&MOD(ROW()-ROW($A$7),$A$6)+ROW($A$7)))&" "&IF($B$6=0,"",INDIRECT("B"&MOD(ROUNDUP((ROW()-ROW($B$7)+1)/$A$6,0)-1,$B$6)+ROW($A$7)))&" "&IF($D$6=0,"",INDIRECT("C"&MOD(ROUNDUP((ROW()-ROW($B$7)+1)/($E$6/$D$6),0)-1,$E$6)+ROW($A$7)))&")","") | I49: =IF(H49="","",COUNTIF($H$7:$H$105,H49)) | J49: =IF(OR(H49="",$G$1=""),"",$B$3&$G$1&H49) | M49: =IF(OR($H49="",$B$6=0),"",INDIRECT("B"&MOD(ROUNDUP((ROW()-ROW($B$7)+1)/$A$6,0)-1,$B$6)+ROW($A$7))) | N49: =M49 | O49: =IF(H49="","",IF($A$6=0,"",INDIRECT("A"&MOD(ROW()-ROW($A$7),$A$6)+ROW($A$7)))) | P49: =IF(O49="","",IF($P$3="否",O49,O49&"cm")) | R49: bullet_point5 | S49: 【豊富なサイズ展開＆体型に合わせたフィット感】S〜5XLまでの豊富なサイズ展開で、幅広い体型に対応。ゆったり着たい方も、タイトに着こなしたい方も、自分にぴったりのサイズが見つかる。通勤、ビジネス、リモートワーク、フォーマルシーンで活躍する万能アイテム！
C50: =IFERROR((VLOOKUP(B50,#REF!,2,FALSE)),"") | F50: =LENB(H50) -> 0 | G50: =IF(AND(0=$B$6,$A$5>0),IF($H50="","",$G$6&"-"&O50),IF(OR($H50="",$C$6=0),"",$G$6&"-"&VLOOKUP(M50,B:C,2,FALSE)&"-"&O50)) | H50: =IF(COUNTA($H$5:H49)-1<$E$6,"("&IF($A$6=0,"",INDIRECT("A"&MOD(ROW()-ROW($A$7),$A$6)+ROW($A$7)))&" "&IF($B$6=0,"",INDIRECT("B"&MOD(ROUNDUP((ROW()-ROW($B$7)+1)/$A$6,0)-1,$B$6)+ROW($A$7)))&" "&IF($D$6=0,"",INDIRECT("C"&MOD(ROUNDUP((ROW()-ROW($B$7)+1)/($E$6/$D$6),0)-1,$E$6)+ROW($A$7)))&")","") | I50: =IF(H50="","",COUNTIF($H$7:$H$105,H50)) | J50: =IF(OR(H50="",$G$1=""),"",$B$3&$G$1&H50) | M50: =IF(OR($H50="",$B$6=0),"",INDIRECT("B"&MOD(ROUNDUP((ROW()-ROW($B$7)+1)/$A$6,0)-1,$B$6)+ROW($A$7))) | N50: =M50 | O50: =IF(H50="","",IF($A$6=0,"",INDIRECT("A"&MOD(ROW()-ROW($A$7),$A$6)+ROW($A$7)))) | P50: =IF(O50="","",IF($P$3="否",O50,O50&"cm"))
...

Sheet Corlor
A1: 颜色 | B1: カラー | C1: ColorMap | D1: カラー2 | E1: 编码
B2: =IF(COUNTA(B$7:B$34)=0,0,COUNTA(B$7:B$34)) -> 28 | C2: =IF(COUNTA(C$7:C$34)=0,0,COUNTA(C$7:C$34)) -> 28 | D2: =IF(COUNTA(D$7:D$34)=0,0,COUNTA(D$7:D$34)) -> 28 | E2: =IF(COUNTA(E$7:E$34)=0,0,COUNTA(E$7:E$34)) -> 28
A3: 黑色 | B3: ブラック | C3: Black | D3: ブラック | E3: 01
A4: 红色 | B4: レッド | C4: Red | D4: レッド | E4: 02
A5: 蓝色 | B5: ブルー | C5: Blue | D5: ブルー | E5: 03
A6: 黄色 | B6: イエロー | C6: Yellow | D6: イエロー | E6: 04
A7: 灰色 | B7: グレー | C7: Gray | D7: グレー | E7: 05
A8: 绿色 | B8: グリーン | C8: Green | D8: グリーン | E8: 06
A9: 粉红色 | B9: ピンク | C9: Pink | D9: ピンク | E9: 07
A10: 咖啡色 | B10: コーヒー | C10: Coffee | D10: コーヒー | E10: 08
A11: 浅蓝色 | B11: ライトブルー | C11: LightBlue | D11: ライトブルー | E11: 09
A12: 酒红 | B12: ワイン | C12: Wine | D12: ワイン | E12: 10
A13: 棕色 | B13: ブラウン | C13: Brown | D13: ブラウン | E13: 11
A14: 杏色（米白） | B14: ベージュ | C14: Beige | D14: ベージュ | E14: 12
... A45: 印花色 | B45: 総柄 | C45: Printing | D45: 総柄 | E45: 43
B46: ブラック(四季通用) | C46: BlackAllSeasons | D46: ブラック(四季通用) | E46: 44
B47: ブルー(薄手夏用) | C47: BlueThin | D47: ブルー(薄手夏用) | E47: 45
B48: ライトブルー(薄手夏用) | C48: LightBlueThin | D48: ライトブルー(薄手夏用) | E48: 46
B49: ブルー(四季通用) | C49: BlueAllSeasons | D49: ブルー(四季通用) | E49: 47
B50: バットマンブラック | C50: BatmanBlack | D50: バットマンブラック | E50: 48
B51: バットマンホワイト | C51: BatmanWhite | D51: バットマンホワイト | E51: 49
B52: バットマンレッド | C52: BatmanRed | D52: バットマンレッド | E52: 50
B53: 長袖パープル | C53: LoSlvPurple | D53: 長袖パープル | E53: 51
B54: 長袖ブルー | C54: LoSlvBlue | D54: 長袖ブルー | E54: 52
A55: 白色（网孔） | B55: ホワイト（メッシュ） | C55: WhiteMesh | D55: ホワイト（メッシュ） | E55: 53
A56: 银 | B56: シルバー | C56: Silver | D56: シルバー | E56: 54
A57: 柔软的米色 | B57: ソフトベージュ | C57: SoftBeige | D57: ソフトベージュ | E57: 55
A58: 绿松石 | B58: ターコイズ | C58: Turquoise | D58: ターコイズ | E58: 56
A59: 玫瑰 | B59: バラ | C59: Rose | D59: バラ | E59: 57
B60: 白（裏起毛あり） | C60: WhiteWBrushing | D60: 白（裏起毛あり）
B61: 紺（裏起毛あり） | C61: NavyABrushing | D61: 紺（裏起毛あり）
B62: 白 | C62: White | D62: 白
B63: 色1 | C63: Color1 | D63: 色1
B64: 色2 | C64: Color2 | D64: 色2
B65: 色3 | C65: Color3 | D65: 色3
B66: 色4 | C66: Color4 | D66: 色4
B67: 色5 | C67: Color5 | D67: 色5
B68: 色6 | C68: Color6 | D68: 色6
B69: 色7 | C69: Color7 | D69: 色7
B70: 色8 | C70: Color8 | D70: 色8
...

Sheet amz自动生成表格
A1: TemplateType=fptcustom | B1: Version=2024.0113 | C1: TemplateSignature=U0hJUlQ= | D1: settings=attributeRow=3&contentLanguageTag=en_US&dataRow=4&feedType=113&headerLanguageTag=en_US&isEdit=false&isExpose=false&isProcessingSummary=false&labelRow=2&metadataVersion=MatprodVm9MVFByb2RfMTIzNA%3D%3D&primaryMarketplaceId=amzn1.mp.o.ATVPDKIKX0DER&ptds=U0hJUlQ%3D&reportProvenance=false&templateIdentifier=df341e0b-6d76-4448-b360-804b0e88d0b5&timestamp=2024-01-13T09%3A58%3A42.290Z | E1: Use ENGLISH to fill this template.DO NOT modify or delete the colored header rows. To expand all optional columns, click the "2" button on the top left. | AI1: Images | AS1: Variation | AZ1: Discovery | CW1: Product Enrichment | DG1: Dimensions | DW1: Fulfillment | EF1: Compliance | HF1: Offer | IC1: B2B
A2: Product Type | B2: Seller SKU | C2: Brand Name | D2: Update Delete | E2: Product Name | F2: Product ID | G2: Product ID Type | H2: Product Description | I2: Item Type Keyword | J2: Closure Type | K2: Style Number | L2: Model Name | M2: Outer Material Type | N2: Outer Material Type | O2: Outer Material Type | P2: Outer Material Type | Q2: Outer Material Type | R2: Manufacturer Part Number | S2: Manufacturer | T2: Product Care Instructions | U2: Your Price | V2: Quantity | W2: Target Gender | X2: Age Range Description | Y2: Shirt Size System | Z2: Shirt Size Class | AA2: Shirt Size Value | AB2: Shirt Size To Range | AC2: Neck Size Value | AD2: Neck Size To Value | AE2: Sleeve Length Value | AF2: Sleeve Length To Value | AG2: Shirt Body Type | AH2: Shirt Height Type | AI2: Main Image URL | AJ2: Other Image URL | AK2: Other Image URL | AL2: Other Image URL | AM2: Other Image URL | AN2: Other Image URL | AO2: Other Image URL | AP2: Other Image URL | AQ2: Other Image URL | AR2: Swatch Image URL | AS2: Parentage | AT2: Parent SKU | AU2: Relationship Type | AV2: Variation Theme | AW2: Package Level | AX2: package_contains_quantity | AY2: package_contains_identifier | AZ2: Key Product Features | BA2: Key Product Features | BB2: Key Product Features | BC2: Key Product Features | BD2: Key Product Features | BE2: Search Terms | BF2: Belt Style | BG2: Collar Type | BH2: Color | BI2: Color Map | BJ2: Control Type | BK2: Department | BL2: Fit Type | BM2: Country/Region as Labeled | BN2: Fur Description | BO2: NeckStyle | BP2: Pattern Style | BQ2: Pocket Description | BR2: Size | BS2: Special Size Type | BT2: Additional Features | BU2: Additional Features | BV2: Additional Features | BW2: Additional Features | BX2: Additional Features | BY2: Style | BZ2: theme | CA2: Top Style | CB2: Water Resistance Level | CC2: Is Autographed | CD2: Item Type Name | CE2: Occasion Type | CF2: Occasion Type | CG2: Occasion Type | CH2: Occasion Type | CI2: Occasion Type | CJ2: Sport Type | CK2: Sport Type | CL2: Athlete | CM2: Team Name | CN2: Season and collection year | CO2: Material type | CP2: Occasion Lifestyle | CQ2: Weave Type | CR2: League Name | CS2: Shaft Style Type | CT2: Product Lifecycle Supply Type | CU2: Pattern | CV2: Item Booking Date | CW2: character | CX2: Fabric Wash | CY2: Sleeve Type | CZ2: Strap Type | DA2: Underwire Type | DB2: Duration Unit | DC2: Certifying Authority Name | DD2: Duration | DE2: Geographic Jurisdiction | DF2: flash_point_unit_of_measure | DG2: Shipping Weight | DH2: Website Shipping Weight Unit Of Measure | DI2: Chest Size | DJ2: Chest Size Unit Of Measure | DK2: Cup Size | DL2: Neck Size | DM2: Neck Size Unit Of Measure | DN2: Size Map | DO2: SleeveLength | DP2: Sleeve Length Unit Of Measure | DQ2: Item Length Unit Of Measure | DR2: Item Length | DS2: Item Width | DT2: Item Height | DU2: Item Width Unit Of Measure | DV2: Item Height Unit Of Measure | DW2: Fulfillment Center ID | DX2: Package Height | DY2: Package Width | DZ2: Package Length | EA2: Package Length Unit Of Measure | EB2: Package Weight | EC2: Package Weight Unit Of Measure | ED2: Package Height Unit Of Measure | EE2: Package Width Unit Of Measure | EF2: Compliance Regulation Type | EG2: Compliance Regulation Type | EH2: Compliance Regulation Type | EI2: Compliance Regulation Type | EJ2: Compliance Regulation Type | EK2: Regulatory Identification | EL2: Regulatory Identification | EM2: Regulatory Identification | EN2: Regulatory Identification | EO2: Regulatory Identification | EP2: Cpsia Warning | EQ2: CPSIA Warning Description | ER2: Fabric Type | ES2: Import Designation | ET2: Item Weight Unit | EU2: Item Weight | EV2: Country/Region of Origin | EW2: Is this product a battery or does it utilize batteries? | EX2: Batteries are Included | EY2: Battery composition | EZ2: Battery type/size | FA2: Battery type/size | FB2: Battery type/size | FC2: Number of batteries | FD2: Number of batteries | FE2: Number of batteries | FF2: Battery weight (grams) | FG2: Battery Weight Unit | FH2: Number of Lithium Metal Cells | FI2: Number of Lithium-ion Cells | FJ2: Lithium Battery Packaging | FK2: Watt hours per battery | FL2: Lithium Battery Energy Content Unit | FM2: Lithium content (grams) | FN2: Lithium Battery Weight Unit | FO2: Applicable Dangerous Goods Regulations | FP2: Applicable Dangerous Goods Regulations | FQ2: Applicable Dangerous Goods Regulations | FR2: Applicable Dangerous Goods Regulations | FS2: Applicable Dangerous Goods Regulations | FT2: UN number | FU2: Safety Data Sheet (SDS) URL | FV2: Volume | FW2: item_volume_unit_of_measure | FX2: legal_compliance_certification_expiration_date | FY2: Regulatory Organization Name | FZ2: Compliance Certification Status | GA2: Flash point (°C)? | GB2: Certification Date of Issue | GC2: Material/Fabric Regulations | GD2: Material/Fabric Regulations | GE2: Material/Fabric Regulations | GF2: Compliance Certification Value | GG2: Legal Compliance Certification | GH2: Categorization/GHS pictograms (select all that apply) | GI2: Categorization/GHS pictograms (select all that apply) | GJ2: Categorization/GHS pictograms (select all that apply) | GK2: California Proposition 65 Warning Type | GL2: California Proposition 65 Chemical Names | GM2: Additional Chemical Name1 | GN2: Additional Chemical Name2 | GO2: Additional Chemical Name3 | GP2: Additional Chemical Name4 | GQ2: Pesticide Marking | GR2: Pesticide Marking | GS2: Pesticide Marking | GT2: Pesticide Registration Status | GU2: Pesticide Registration Status | GV2: Pesticide Registration Status | GW2: Pesticide Certification Number | GX2: Pesticide Certification Number | GY2: Pesticide Certification Number | GZ2: Radio Frequency Emission & Authorization Status | HA2: SDoC Contact Email Address | HB2: SDOC Contact US Phone Number | HC2: SDoC Contact Name | HD2: FCC ID | HE2: SDoC Contact US Mailing Address | HF2: List Price | HG2: Minimum Advertised Price | HH2: Currency | HI2: Item Condition | HJ2: Condition Note | HK2: Product Tax Code | HL2: Handling Time | HM2: Launch Date | HN2: Release Date | HO2: Restock Date | HP2: Sale Price | HQ2: Sale Start Date | HR2: Sale End Date | HS2: Offer End Date | HT2: Max Aggregate Ship Quantity | HU2: Package Quantity | HV2: Number of Items | HW2: Offering Can Be Gift Messaged | HX2: Is Gift Wrap Available | HY2: Is Discontinued by Manufacturer | HZ2: Max Order Quantity | IA2: Shipping-Template | IB2: Offer Start Date | IC2: Business Price | ID2: Quantity Price Type | IE2: Quantity Lower Bound 1 | IF2: Quantity Price 1 | IG2: Quantity Lower Bound 2 | IH2: Quantity Price 2 | II2: Quantity Lower Bound 3 | IJ2: Quantity Price 3 | IK2: Quantity Lower Bound 4 | IL2: Quantity Price 4 | IM2: Quantity Lower Bound 5 | IN2: Quantity Price 5 | IO2: Progressive Discount Type | IP2: Progressive Discount Lower Bound 1 | IQ2: Progressive Discount Value 1 | IR2: Progressive Discount Lower Bound 2 | IS2: Progressive Discount Value 2 | IT2: Progressive Discount Lower Bound 3 | IU2: Progressive Discount Value 3 | IV2: National Stock Number | IW2: United Nations Standard Products and Services Code | IX2: Pricing Action
A3: feed_product_type | B3: item_sku | C3: brand_name | D3: update_delete | E3: item_name | F3: external_product_id | G3: external_product_id_type | H3: product_description | I3: item_type | J3: closure_type | K3: model | L3: model_name | M3: outer_material_type1 | N3: outer_material_type2 | O3: outer_material_type3 | P3: outer_material_type4 | Q3: outer_material_type5 | R3: part_number | S3: manufacturer | T3: care_instructions | U3: standard_price | V3: quantity | W3: target_gender | X3: age_range_description | Y3: shirt_size_system | Z3: shirt_size_class | AA3: shirt_size | AB3: shirt_size_to | AC3: shirt_neck_size | AD3: shirt_neck_size_to | AE3: shirt_sleeve_length | AF3: shirt_sleeve_length_to | AG3: shirt_body_type | AH3: shirt_height_type | AI3: main_image_url | AJ3: other_image_url1 | AK3: other_image_url2 | AL3: other_image_url3 | AM3: other_image_url4 | AN3: other_image_url5 | AO3: other_image_url6 | AP3: other_image_url7 | AQ3: other_image_url8 | AR3: swatch_image_url | AS3: parent_child | AT3: parent_sku | AU3: relationship_type | AV3: variation_theme | AW3: package_level | AX3: package_contains_quantity | AY3: package_contains_identifier | AZ3: bullet_point1 | BA3: bullet_point2 | BB3: bullet_point3 | BC3: bullet_point4 | BD3: bullet_point5 | BE3: generic_keywords | BF3: belt_style | BG3: collar_style | BH3: color_name | BI3: color_map | BJ3: control_type | BK3: department_name | BL3: fit_type | BM3: country_as_labeled | BN3: fur_description | BO3: neck_style | BP3: pattern_type | BQ3: pocket_description | BR3: size_name | BS3: special_size_type | BT3: special_features1 | BU3: special_features2 | BV3: special_features3 | BW3: special_features4 | BX3: special_features5 | BY3: style_name | BZ3: theme | CA3: top_style | CB3: water_resistance_level | CC3: is_autographed | CD3: item_type_name | CE3: occasion_type1 | CF3: occasion_type2 | CG3: occasion_type3 | CH3: occasion_type4 | CI3: occasion_type5 | CJ3: sport_type1 | CK3: sport_type2 | CL3: athlete | CM3: team_name | CN3: collection_name | CO3: material_type | CP3: lifestyle | CQ3: weave_type | CR3: league_name | CS3: shaft_style_type | CT3: lifecycle_supply_type | CU3: pattern_name | CV3: item_booking_date | CW3: subject_character | CX3: fabric_wash | CY3: sleeve_type | CZ3: strap_type | DA3: underwire_type | DB3: duration_unit_of_measure | DC3: legal_compliance_certification_certifying_authority_name | DD3: duration | DE3: legal_compliance_certification_geographic_jurisdiction | DF3: flash_point_unit_of_measure | DG3: website_shipping_weight | DH3: website_shipping_weight_unit_of_measure | DI3: chest_size | DJ3: chest_size_unit_of_measure | DK3: cup_size | DL3: neck_size | DM3: neck_size_unit_of_measure | DN3: size_map | DO3: sleeve_length | DP3: sleeve_length_unit_of_measure | DQ3: item_length_unit_of_measure | DR3: item_length | DS3: item_width | DT3: item_height | DU3: item_width_unit_of_measure | DV3: item_height_unit_of_measure | DW3: fulfillment_center_id | DX3: package_height | DY3: package_width | DZ3: package_length | EA3: package_length_unit_of_measure | EB3: package_weight | EC3: package_weight_unit_of_measure | ED3: package_height_unit_of_measure | EE3: package_width_unit_of_measure | EF3: regulation_type1 | EG3: regulation_type2 | EH3: regulation_type3 | EI3: regulation_type4 | EJ3: regulation_type5 | EK3: regulatory_compliance_certification_value1 | EL3: regulatory_compliance_certification_value2 | EM3: regulatory_compliance_certification_value3 | EN3: regulatory_compliance_certification_value4 | EO3: regulatory_compliance_certification_value5 | EP3: cpsia_cautionary_statement | EQ3: cpsia_cautionary_description | ER3: fabric_type | ES3: import_designation | ET3: item_weight_unit_of_measure | EU3: item_weight | EV3: country_of_origin | EW3: batteries_required | EX3: are_batteries_included | EY3: battery_cell_composition | EZ3: battery_type1 | FA3: battery_type2 | FB3: battery_type3 | FC3: number_of_batteries1 | FD3: number_of_batteries2 | FE3: number_of_batteries3 | FF3: battery_weight | FG3: battery_weight_unit_of_measure | FH3: number_of_lithium_metal_cells | FI3: number_of_lithium_ion_cells | FJ3: lithium_battery_packaging | FK3: lithium_battery_energy_content | FL3: lithium_battery_energy_content_unit_of_measure | FM3: lithium_battery_weight | FN3: lithium_battery_weight_unit_of_measure | FO3: supplier_declared_dg_hz_regulation1 | FP3: supplier_declared_dg_hz_regulation2 | FQ3: supplier_declared_dg_hz_regulation3 | FR3: supplier_declared_dg_hz_regulation4 | FS3: supplier_declared_dg_hz_regulation5 | FT3: hazmat_united_nations_regulatory_id | FU3: safety_data_sheet_url | FV3: item_volume | FW3: item_volume_unit_of_measure | FX3: legal_compliance_certification_expiration_date | FY3: legal_compliance_certification_regulatory_organization_name | FZ3: legal_compliance_certification_status | GA3: flash_point | GB3: legal_compliance_certification_date_of_issue | GC3: supplier_declared_material_regulation1 | GD3: supplier_declared_material_regulation2 | GE3: supplier_declared_material_regulation3 | GF3: legal_compliance_certification_metadata | GG3: legal_compliance_certification_value | GH3: ghs_classification_class1 | GI3: ghs_classification_class2 | GJ3: ghs_classification_class3 | GK3: california_proposition_65_compliance_type | GL3: california_proposition_65_chemical_names1 | GM3: california_proposition_65_chemical_names2 | GN3: california_proposition_65_chemical_names3 | GO3: california_proposition_65_chemical_names4 | GP3: california_proposition_65_chemical_names5 | GQ3: pesticide_marking_type1 | GR3: pesticide_marking_type2 | GS3: pesticide_marking_type3 | GT3: pesticide_marking_registration_status1 | GU3: pesticide_marking_registration_status2 | GV3: pesticide_marking_registration_status3 | GW3: pesticide_marking_certification_number1 | GX3: pesticide_marking_certification_number2 | GY3: pesticide_marking_certification_number3 | GZ3: fcc_radio_frequency_emission_compliance_registration_status | HA3: fcc_radio_frequency_emission_compliance_point_of_contact_email | HB3: fcc_radio_frequency_emission_compliance_point_of_contact_phone_number | HC3: fcc_radio_frequency_emission_compliance_point_of_contact_name | HD3: fcc_radio_frequency_emission_compliance_identification_number | HE3: fcc_radio_frequency_emission_compliance_point_of_contact_address | HF3: list_price | HG3: map_price | HH3: currency | HI3: condition_type | HJ3: condition_note | HK3: product_tax_code | HL3: fulfillment_latency | HM3: product_site_launch_date | HN3: merchant_release_date | HO3: restock_date | HP3: sale_price | HQ3: sale_from_date | HR3: sale_end_date | HS3: offering_end_date | HT3: max_aggregate_ship_quantity | HU3: item_package_quantity | HV3: number_of_items | HW3: offering_can_be_gift_messaged | HX3: offering_can_be_giftwrapped | HY3: is_discontinued_by_manufacturer | HZ3: max_order_quantity | IA3: merchant_shipping_group_name | IB3: offering_start_date | IC3: business_price | ID3: quantity_price_type | IE3: quantity_lower_bound1 | IF3: quantity_price1 | IG3: quantity_lower_bound2 | IH3: quantity_price2 | II3: quantity_lower_bound3 | IJ3: quantity_price3 | IK3: quantity_lower_bound4 | IL3: quantity_price4 | IM3: quantity_lower_bound5 | IN3: quantity_price5 | IO3: progressive_discount_type | IP3: progressive_discount_lower_bound1 | IQ3: progressive_discount_value1 | IR3: progressive_discount_lower_bound2 | IS3: progressive_discount_value2 | IT3: progressive_discount_lower_bound3 | IU3: progressive_discount_value3 | IV3: national_stock_number | IW3: unspsc_code | IX3: pricing_action
A4: =IF(B4="","",step01标题尺码信息!$B$3) | B4: =IF(step01标题尺码信息!G6="","",step01标题尺码信息!G6) | C4: =IF(B4="","",step01标题尺码信息!$E$3) | D4: =IF(B4="","","Update") | E4: =IF(B4="","",VLOOKUP(B4,step01标题尺码信息!G:P,4,0)) | H4: =IF(B4="","",step01标题尺码信息!$R$19) | I4: =IF(B4="","","novelty-t-shirts") | M4: =IF(B4="","","Synthetic") | U4: =IF(B4="","",step01标题尺码信息!$S$1) | V4: =IF(B4="","",1000) | W4: =IF(B4="","",step01标题尺码信息!$V$1) | X4: =IF(B4="","",step01标题尺码信息!$V$2) | AS4: Parent | AU4: Variation | AV4: =IF(B4="","",step01标题尺码信息!$T$36) | AZ4: =IF(B4="","",step01标题尺码信息!$S$41) | BA4: =IF(B4="","",step01标题尺码信息!$S$43) | BB4: =IF(B4="","",step01标题尺码信息!$S$45) | BC4: =IF(B4="","",step01标题尺码信息!$S$47) | BD4: =IF(B4="","",step01标题尺码信息!$S$49) | BE4: =IF(B4="","",step01标题尺码信息!$S$53) | BH4: =IF(B4="","",IF(DX4="Parent","",VLOOKUP(B4,step01标题尺码信息!G:P,7,0))) | BI4: =IF(B4="","",IF(DX4="Parent","",VLOOKUP(B4,step01标题尺码信息!G:P,8,0))) | BK4: =IF(B4="","","Unisex Adult") | BL4: =IF(B4="","","Regular") | BO4: =IF(B4="","","Crewneck") | BR4: =IF(B4="","",IF(AS4="Parent","",VLOOKUP(B4,step01标题尺码信息!G:P,9,0))) | CY4: =IF(B4="","","Short Sleeve") | DG4: =IF(B4="","",step01标题尺码信息!$T$30) | DH4: =IF(B4="","","KG") | DN4: =BR4 | DW4: =IF(B4="","","DEFAULT") | ER4: =IF(B4="","",step01标题尺码信息!$T$37) | ES4: =IF(B4="","","Imported") | HF4: =IF(B4="","",step01标题尺码信息!$S$2) | HH4: =IF(B4="","","USD") | HI4: =IF(B4="","","NEW") | HL4: =IF(B4="","","10") | IA4: =IF(B4="","","Migrated Template")
